2020-06-25 15:56:20,471 ERROR: Exception on /uploadfile [POST] [in /Users/elee/ubuntu/microblog/venv/lib/python3.7/site-packages/flask/app.py:1761]
Traceback (most recent call last):
  File "/Users/elee/ubuntu/microblog/venv/lib/python3.7/site-packages/flask/app.py", line 2292, in wsgi_app
    response = self.full_dispatch_request()
  File "/Users/elee/ubuntu/microblog/venv/lib/python3.7/site-packages/flask/app.py", line 1815, in full_dispatch_request
    rv = self.handle_user_exception(e)
  File "/Users/elee/ubuntu/microblog/venv/lib/python3.7/site-packages/flask/app.py", line 1718, in handle_user_exception
    reraise(exc_type, exc_value, tb)
  File "/Users/elee/ubuntu/microblog/venv/lib/python3.7/site-packages/flask/_compat.py", line 35, in reraise
    raise value
  File "/Users/elee/ubuntu/microblog/venv/lib/python3.7/site-packages/flask/app.py", line 1813, in full_dispatch_request
    rv = self.dispatch_request()
  File "/Users/elee/ubuntu/microblog/venv/lib/python3.7/site-packages/flask/app.py", line 1799, in dispatch_request
    return self.view_functions[rule.endpoint](**req.view_args)
  File "/Users/elee/ubuntu/microblog/venv/lib/python3.7/site-packages/flask_login/utils.py", line 228, in decorated_view
    return func(*args, **kwargs)
  File "/Users/elee/practice_docker/microblog/app/main/routes.py", line 181, in upload_file
    file.save(os.path.join(current_app.config['UPLOAD_FOLDER'], filename))
  File "/Users/elee/ubuntu/microblog/venv/lib/python3.7/site-packages/werkzeug/datastructures.py", line 2725, in save
    dst = open(dst, 'wb')
FileNotFoundError: [Errno 2] No such file or directory: '/Users/elee/practice_docker/microblog/uploads/hello_world.txt'
2020-06-25 16:04:53,434 ERROR: Exception on /uploadfile [POST] [in /Users/elee/ubuntu/microblog/venv/lib/python3.7/site-packages/flask/app.py:1761]
Traceback (most recent call last):
  File "/Users/elee/ubuntu/microblog/venv/lib/python3.7/site-packages/flask/app.py", line 2292, in wsgi_app
    response = self.full_dispatch_request()
  File "/Users/elee/ubuntu/microblog/venv/lib/python3.7/site-packages/flask/app.py", line 1815, in full_dispatch_request
    rv = self.handle_user_exception(e)
  File "/Users/elee/ubuntu/microblog/venv/lib/python3.7/site-packages/flask/app.py", line 1718, in handle_user_exception
    reraise(exc_type, exc_value, tb)
  File "/Users/elee/ubuntu/microblog/venv/lib/python3.7/site-packages/flask/_compat.py", line 35, in reraise
    raise value
  File "/Users/elee/ubuntu/microblog/venv/lib/python3.7/site-packages/flask/app.py", line 1813, in full_dispatch_request
    rv = self.dispatch_request()
  File "/Users/elee/ubuntu/microblog/venv/lib/python3.7/site-packages/flask/app.py", line 1799, in dispatch_request
    return self.view_functions[rule.endpoint](**req.view_args)
  File "/Users/elee/ubuntu/microblog/venv/lib/python3.7/site-packages/flask_login/utils.py", line 228, in decorated_view
    return func(*args, **kwargs)
  File "/Users/elee/practice_docker/microblog/app/main/routes.py", line 181, in upload_file
    file.save(os.path.join(current_app.config['UPLOAD_FOLDER'], filename))
  File "/Users/elee/ubuntu/microblog/venv/lib/python3.7/site-packages/werkzeug/datastructures.py", line 2725, in save
    dst = open(dst, 'wb')
FileNotFoundError: [Errno 2] No such file or directory: '/Users/elee/practice_docker/microblog/uploads/hello_world.txt'
2020-06-25 16:05:20,520 INFO: Microblog startup [in /Users/elee/practice_docker/microblog/app/__init__.py:77]
2020-06-25 16:06:01,555 ERROR: Exception on /uploadfile [POST] [in /Users/elee/ubuntu/microblog/venv/lib/python3.7/site-packages/flask/app.py:1761]
Traceback (most recent call last):
  File "/Users/elee/ubuntu/microblog/venv/lib/python3.7/site-packages/flask/app.py", line 2292, in wsgi_app
    response = self.full_dispatch_request()
  File "/Users/elee/ubuntu/microblog/venv/lib/python3.7/site-packages/flask/app.py", line 1815, in full_dispatch_request
    rv = self.handle_user_exception(e)
  File "/Users/elee/ubuntu/microblog/venv/lib/python3.7/site-packages/flask/app.py", line 1718, in handle_user_exception
    reraise(exc_type, exc_value, tb)
  File "/Users/elee/ubuntu/microblog/venv/lib/python3.7/site-packages/flask/_compat.py", line 35, in reraise
    raise value
  File "/Users/elee/ubuntu/microblog/venv/lib/python3.7/site-packages/flask/app.py", line 1813, in full_dispatch_request
    rv = self.dispatch_request()
  File "/Users/elee/ubuntu/microblog/venv/lib/python3.7/site-packages/flask/app.py", line 1799, in dispatch_request
    return self.view_functions[rule.endpoint](**req.view_args)
  File "/Users/elee/ubuntu/microblog/venv/lib/python3.7/site-packages/flask_login/utils.py", line 228, in decorated_view
    return func(*args, **kwargs)
  File "/Users/elee/practice_docker/microblog/app/main/routes.py", line 181, in upload_file
    file.save(os.path.join(current_app.config['UPLOAD_FOLDER'], filename))
  File "/Users/elee/ubuntu/microblog/venv/lib/python3.7/site-packages/werkzeug/datastructures.py", line 2725, in save
    dst = open(dst, 'wb')
FileNotFoundError: [Errno 2] No such file or directory: '/Users/elee/practice_docker/microblog/uploads/hello_world.txt'
2020-06-25 16:06:50,462 INFO: Microblog startup [in /Users/elee/practice_docker/microblog/app/__init__.py:77]
2020-06-25 16:07:29,433 INFO: Microblog startup [in /Users/elee/practice_docker/microblog/app/__init__.py:77]
2020-06-25 16:08:02,583 INFO: Microblog startup [in /Users/elee/practice_docker/microblog/app/__init__.py:77]
2020-06-25 16:08:39,608 ERROR: Exception on /uploadfile [POST] [in /Users/elee/ubuntu/microblog/venv/lib/python3.7/site-packages/flask/app.py:1761]
Traceback (most recent call last):
  File "/Users/elee/ubuntu/microblog/venv/lib/python3.7/site-packages/flask/app.py", line 2292, in wsgi_app
    response = self.full_dispatch_request()
  File "/Users/elee/ubuntu/microblog/venv/lib/python3.7/site-packages/flask/app.py", line 1815, in full_dispatch_request
    rv = self.handle_user_exception(e)
  File "/Users/elee/ubuntu/microblog/venv/lib/python3.7/site-packages/flask/app.py", line 1718, in handle_user_exception
    reraise(exc_type, exc_value, tb)
  File "/Users/elee/ubuntu/microblog/venv/lib/python3.7/site-packages/flask/_compat.py", line 35, in reraise
    raise value
  File "/Users/elee/ubuntu/microblog/venv/lib/python3.7/site-packages/flask/app.py", line 1813, in full_dispatch_request
    rv = self.dispatch_request()
  File "/Users/elee/ubuntu/microblog/venv/lib/python3.7/site-packages/flask/app.py", line 1799, in dispatch_request
    return self.view_functions[rule.endpoint](**req.view_args)
  File "/Users/elee/ubuntu/microblog/venv/lib/python3.7/site-packages/flask_login/utils.py", line 228, in decorated_view
    return func(*args, **kwargs)
  File "/Users/elee/practice_docker/microblog/app/main/routes.py", line 181, in upload_file
    file.save(os.path.join(current_app.config['UPLOAD_FOLDER'], filename))
  File "/Users/elee/ubuntu/microblog/venv/lib/python3.7/site-packages/werkzeug/datastructures.py", line 2725, in save
    dst = open(dst, 'wb')
FileNotFoundError: [Errno 2] No such file or directory: '/Users/elee/practice_docker/microblog/uploads/hello_world.txt'
2020-06-25 16:13:27,655 INFO: Microblog startup [in /Users/elee/practice_docker/microblog/app/__init__.py:77]
2020-06-25 16:13:34,452 ERROR: Exception on /uploadfile [POST] [in /Users/elee/ubuntu/microblog/venv/lib/python3.7/site-packages/flask/app.py:1761]
Traceback (most recent call last):
  File "/Users/elee/ubuntu/microblog/venv/lib/python3.7/site-packages/flask/app.py", line 2292, in wsgi_app
    response = self.full_dispatch_request()
  File "/Users/elee/ubuntu/microblog/venv/lib/python3.7/site-packages/flask/app.py", line 1815, in full_dispatch_request
    rv = self.handle_user_exception(e)
  File "/Users/elee/ubuntu/microblog/venv/lib/python3.7/site-packages/flask/app.py", line 1718, in handle_user_exception
    reraise(exc_type, exc_value, tb)
  File "/Users/elee/ubuntu/microblog/venv/lib/python3.7/site-packages/flask/_compat.py", line 35, in reraise
    raise value
  File "/Users/elee/ubuntu/microblog/venv/lib/python3.7/site-packages/flask/app.py", line 1813, in full_dispatch_request
    rv = self.dispatch_request()
  File "/Users/elee/ubuntu/microblog/venv/lib/python3.7/site-packages/flask/app.py", line 1799, in dispatch_request
    return self.view_functions[rule.endpoint](**req.view_args)
  File "/Users/elee/ubuntu/microblog/venv/lib/python3.7/site-packages/flask_login/utils.py", line 228, in decorated_view
    return func(*args, **kwargs)
  File "/Users/elee/practice_docker/microblog/app/main/routes.py", line 181, in upload_file
    if not os.path.exists(UPLOAD_FOLDER):
NameError: name 'UPLOAD_FOLDER' is not defined
2020-06-25 16:13:37,662 ERROR: Exception on /uploadfile [POST] [in /Users/elee/ubuntu/microblog/venv/lib/python3.7/site-packages/flask/app.py:1761]
Traceback (most recent call last):
  File "/Users/elee/ubuntu/microblog/venv/lib/python3.7/site-packages/flask/app.py", line 2292, in wsgi_app
    response = self.full_dispatch_request()
  File "/Users/elee/ubuntu/microblog/venv/lib/python3.7/site-packages/flask/app.py", line 1815, in full_dispatch_request
    rv = self.handle_user_exception(e)
  File "/Users/elee/ubuntu/microblog/venv/lib/python3.7/site-packages/flask/app.py", line 1718, in handle_user_exception
    reraise(exc_type, exc_value, tb)
  File "/Users/elee/ubuntu/microblog/venv/lib/python3.7/site-packages/flask/_compat.py", line 35, in reraise
    raise value
  File "/Users/elee/ubuntu/microblog/venv/lib/python3.7/site-packages/flask/app.py", line 1813, in full_dispatch_request
    rv = self.dispatch_request()
  File "/Users/elee/ubuntu/microblog/venv/lib/python3.7/site-packages/flask/app.py", line 1799, in dispatch_request
    return self.view_functions[rule.endpoint](**req.view_args)
  File "/Users/elee/ubuntu/microblog/venv/lib/python3.7/site-packages/flask_login/utils.py", line 228, in decorated_view
    return func(*args, **kwargs)
  File "/Users/elee/practice_docker/microblog/app/main/routes.py", line 181, in upload_file
    if not os.path.exists(UPLOAD_FOLDER):
NameError: name 'UPLOAD_FOLDER' is not defined
