2020-07-08 12:51:51,423 ERROR: Exception on /figure_maker [GET] [in /Users/elee/ubuntu/microblog/venv/lib/python3.7/site-packages/flask/app.py:1761]
Traceback (most recent call last):
  File "/Users/elee/ubuntu/microblog/venv/lib/python3.7/site-packages/flask/app.py", line 2292, in wsgi_app
    response = self.full_dispatch_request()
  File "/Users/elee/ubuntu/microblog/venv/lib/python3.7/site-packages/flask/app.py", line 1815, in full_dispatch_request
    rv = self.handle_user_exception(e)
  File "/Users/elee/ubuntu/microblog/venv/lib/python3.7/site-packages/flask/app.py", line 1718, in handle_user_exception
    reraise(exc_type, exc_value, tb)
  File "/Users/elee/ubuntu/microblog/venv/lib/python3.7/site-packages/flask/_compat.py", line 35, in reraise
    raise value
  File "/Users/elee/ubuntu/microblog/venv/lib/python3.7/site-packages/flask/app.py", line 1813, in full_dispatch_request
    rv = self.dispatch_request()
  File "/Users/elee/ubuntu/microblog/venv/lib/python3.7/site-packages/flask/app.py", line 1799, in dispatch_request
    return self.view_functions[rule.endpoint](**req.view_args)
  File "/Users/elee/ubuntu/microblog/venv/lib/python3.7/site-packages/flask_login/utils.py", line 228, in decorated_view
    return func(*args, **kwargs)
  File "/Users/elee/heroku_v6/microblog/app/main/routes.py", line 370, in make_figure
    return render_template('figure_makerr.html')
  File "/Users/elee/ubuntu/microblog/venv/lib/python3.7/site-packages/flask/templating.py", line 134, in render_template
    return _render(ctx.app.jinja_env.get_or_select_template(template_name_or_list),
  File "/Users/elee/ubuntu/microblog/venv/lib/python3.7/site-packages/jinja2/environment.py", line 869, in get_or_select_template
    return self.get_template(template_name_or_list, parent, globals)
  File "/Users/elee/ubuntu/microblog/venv/lib/python3.7/site-packages/jinja2/environment.py", line 830, in get_template
    return self._load_template(name, self.make_globals(globals))
  File "/Users/elee/ubuntu/microblog/venv/lib/python3.7/site-packages/jinja2/environment.py", line 804, in _load_template
    template = self.loader.load(self, name, globals)
  File "/Users/elee/ubuntu/microblog/venv/lib/python3.7/site-packages/jinja2/loaders.py", line 113, in load
    source, filename, uptodate = self.get_source(environment, name)
  File "/Users/elee/ubuntu/microblog/venv/lib/python3.7/site-packages/flask/templating.py", line 58, in get_source
    return self._get_source_fast(environment, template)
  File "/Users/elee/ubuntu/microblog/venv/lib/python3.7/site-packages/flask/templating.py", line 86, in _get_source_fast
    raise TemplateNotFound(template)
jinja2.exceptions.TemplateNotFound: figure_makerr.html
2020-07-08 12:52:06,949 INFO: Microblog startup [in /Users/elee/heroku_v6/microblog/app/__init__.py:86]
2020-07-10 10:42:44,914 INFO: Microblog startup [in ./app/__init__.py:86]
2020-07-10 10:49:06,810 INFO: Microblog startup [in ./app/__init__.py:86]
2020-07-10 11:42:41,290 INFO: Microblog startup [in ./app/__init__.py:86]
2020-07-10 11:42:45,631 ERROR: Unhandled exception [in ./app/tasks.py:93]
Traceback (most recent call last):
  File "./app/tasks.py", line 87, in graph_figures
    upload_pdf_files(output_path, "leelab-processed", f"graphs_{filename}.pdf")
  File "./app/s3_demo.py", line 57, in upload_pdf_files
    response = s3_client.upload_file(file_path, bucket, object_name, ExtraArgs={'ContentType': 'application/pdf', 'Content-Disposition': 'inline'})
  File "/Users/elee/ubuntu/microblog/venv/lib/python3.7/site-packages/boto3/s3/inject.py", line 131, in upload_file
    extra_args=ExtraArgs, callback=Callback)
  File "/Users/elee/ubuntu/microblog/venv/lib/python3.7/site-packages/boto3/s3/transfer.py", line 277, in upload_file
    filename, bucket, key, extra_args, subscribers)
  File "/Users/elee/ubuntu/microblog/venv/lib/python3.7/site-packages/s3transfer/manager.py", line 304, in upload
    self._validate_all_known_args(extra_args, self.ALLOWED_UPLOAD_ARGS)
  File "/Users/elee/ubuntu/microblog/venv/lib/python3.7/site-packages/s3transfer/manager.py", line 446, in _validate_all_known_args
    kwarg, ', '.join(allowed)))
ValueError: Invalid extra_args key 'Content-Disposition', must be one of: ACL, CacheControl, ContentDisposition, ContentEncoding, ContentLanguage, ContentType, Expires, GrantFullControl, GrantRead, GrantReadACP, GrantWriteACP, Metadata, RequestPayer, ServerSideEncryption, StorageClass, SSECustomerAlgorithm, SSECustomerKey, SSECustomerKeyMD5, SSEKMSKeyId, Tagging, WebsiteRedirectLocation
2020-07-10 11:43:55,170 INFO: Microblog startup [in ./app/__init__.py:86]
2020-07-10 11:50:00,103 INFO: Microblog startup [in ./app/__init__.py:86]
2020-07-10 12:28:04,840 INFO: Microblog startup [in ./app/__init__.py:86]
2020-07-10 12:31:51,847 INFO: Microblog startup [in ./app/__init__.py:86]
2020-07-10 12:32:31,475 INFO: Microblog startup [in ./app/__init__.py:86]
2020-07-10 12:35:35,638 INFO: Microblog startup [in ./app/__init__.py:86]
2020-07-10 12:42:38,667 INFO: Microblog startup [in ./app/__init__.py:86]
2020-07-10 12:44:15,734 INFO: Microblog startup [in ./app/__init__.py:86]
2020-07-10 13:26:36,496 INFO: Microblog startup [in ./app/__init__.py:86]
2020-07-10 14:19:39,218 INFO: Microblog startup [in ./app/__init__.py:86]
